[2023-06-19 20:22:04,144] {taskinstance.py:1179} INFO - Dependencies all met for <TaskInstance: dag_weather.extract_data manual__2023-06-19T19:55:51.283782+00:00 [queued]>
[2023-06-19 20:22:04,158] {taskinstance.py:1179} INFO - Dependencies all met for <TaskInstance: dag_weather.extract_data manual__2023-06-19T19:55:51.283782+00:00 [queued]>
[2023-06-19 20:22:04,158] {taskinstance.py:1376} INFO - 
--------------------------------------------------------------------------------
[2023-06-19 20:22:04,158] {taskinstance.py:1377} INFO - Starting attempt 6 of 6
[2023-06-19 20:22:04,158] {taskinstance.py:1378} INFO - 
--------------------------------------------------------------------------------
[2023-06-19 20:22:04,178] {taskinstance.py:1397} INFO - Executing <Task(PythonOperator): extract_data> on 2023-06-19 19:55:51.283782+00:00
[2023-06-19 20:22:04,184] {standard_task_runner.py:52} INFO - Started process 259 to run task
[2023-06-19 20:22:04,187] {standard_task_runner.py:79} INFO - Running: ['***', 'tasks', 'run', 'dag_weather', 'extract_data', 'manual__2023-06-19T19:55:51.283782+00:00', '--job-id', '60', '--raw', '--subdir', 'DAGS_FOLDER/dag_weather.py', '--cfg-path', '/tmp/tmpijnlvdeb', '--error-file', '/tmp/tmphee29qks']
[2023-06-19 20:22:04,189] {standard_task_runner.py:80} INFO - Job 60: Subtask extract_data
[2023-06-19 20:22:04,264] {task_command.py:371} INFO - Running <TaskInstance: dag_weather.extract_data manual__2023-06-19T19:55:51.283782+00:00 [running]> on host e8321a208274
[2023-06-19 20:22:04,343] {taskinstance.py:1591} INFO - Exporting the following env vars:
AIRFLOW_CTX_DAG_OWNER=MariaRO
AIRFLOW_CTX_DAG_ID=dag_weather
AIRFLOW_CTX_TASK_ID=extract_data
AIRFLOW_CTX_EXECUTION_DATE=2023-06-19T19:55:51.283782+00:00
AIRFLOW_CTX_TRY_NUMBER=6
AIRFLOW_CTX_DAG_RUN_ID=manual__2023-06-19T19:55:51.283782+00:00
[2023-06-19 20:22:04,345] {logging_mixin.py:115} INFO - ***************
[2023-06-19 20:22:04,345] {logging_mixin.py:115} INFO - 2023-06-19
[2023-06-19 20:22:14,361] {logging_mixin.py:115} INFO - HTTPConnectionPool(host='api.weatherapi.com', port=80): Max retries exceeded with url: /v1/history.json?key=a6c998288a8944c8a84204951231505&q=Buenos%20Aires&dt=2023-06-15 (Caused by NewConnectionError('<urllib3.connection.HTTPConnection object at 0x7f4bbb31f090>: Failed to establish a new connection: [Errno -3] Temporary failure in name resolution'))
[2023-06-19 20:22:15,612] {taskinstance.py:1909} ERROR - Task failed with exception
Traceback (most recent call last):
  File "/home/airflow/.local/lib/python3.7/site-packages/airflow/operators/python.py", line 171, in execute
    return_value = self.execute_callable()
  File "/home/airflow/.local/lib/python3.7/site-packages/airflow/operators/python.py", line 189, in execute_callable
    return self.python_callable(*self.op_args, **self.op_kwargs)
  File "/opt/airflow/dags/dag_weather.py", line 50, in extract_data
    df.to_csv(dag_path+f'/data/01_raw/{exec_date}.csv', index=False)
  File "/home/airflow/.local/lib/python3.7/site-packages/pandas/core/generic.py", line 3482, in to_csv
    storage_options=storage_options,
  File "/home/airflow/.local/lib/python3.7/site-packages/pandas/io/formats/format.py", line 1105, in to_csv
    csv_formatter.save()
  File "/home/airflow/.local/lib/python3.7/site-packages/pandas/io/formats/csvs.py", line 243, in save
    storage_options=self.storage_options,
  File "/home/airflow/.local/lib/python3.7/site-packages/pandas/io/common.py", line 707, in get_handle
    newline="",
FileNotFoundError: [Errno 2] No such file or directory: '/opt/airflow/data/01_raw/2023-06-19.csv'
[2023-06-19 20:22:15,623] {taskinstance.py:1420} INFO - Marking task as FAILED. dag_id=dag_weather, task_id=extract_data, execution_date=20230619T195551, start_date=20230619T202204, end_date=20230619T202215
[2023-06-19 20:22:15,635] {standard_task_runner.py:97} ERROR - Failed to execute job 60 for task extract_data ([Errno 2] No such file or directory: '/opt/airflow/data/01_raw/2023-06-19.csv'; 259)
[2023-06-19 20:22:15,662] {local_task_job.py:156} INFO - Task exited with return code 1
[2023-06-19 20:22:15,702] {local_task_job.py:273} INFO - 0 downstream tasks scheduled from follow-on schedule check
