[2023-07-13 18:53:51,013] {taskinstance.py:1179} INFO - Dependencies all met for <TaskInstance: dag_weather.send_email manual__2023-07-13T18:53:39.043029+00:00 [queued]>
[2023-07-13 18:53:51,028] {taskinstance.py:1179} INFO - Dependencies all met for <TaskInstance: dag_weather.send_email manual__2023-07-13T18:53:39.043029+00:00 [queued]>
[2023-07-13 18:53:51,029] {taskinstance.py:1376} INFO - 
--------------------------------------------------------------------------------
[2023-07-13 18:53:51,029] {taskinstance.py:1377} INFO - Starting attempt 1 of 6
[2023-07-13 18:53:51,029] {taskinstance.py:1378} INFO - 
--------------------------------------------------------------------------------
[2023-07-13 18:53:51,049] {taskinstance.py:1397} INFO - Executing <Task(PythonOperator): send_email> on 2023-07-13 18:53:39.043029+00:00
[2023-07-13 18:53:51,054] {standard_task_runner.py:52} INFO - Started process 232 to run task
[2023-07-13 18:53:51,058] {standard_task_runner.py:79} INFO - Running: ['***', 'tasks', 'run', 'dag_weather', 'send_email', 'manual__2023-07-13T18:53:39.043029+00:00', '--job-id', '77', '--raw', '--subdir', 'DAGS_FOLDER/dag_weather.py', '--cfg-path', '/tmp/tmpc3tx5gyv', '--error-file', '/tmp/tmp3uauk_fu']
[2023-07-13 18:53:51,059] {standard_task_runner.py:80} INFO - Job 77: Subtask send_email
[2023-07-13 18:53:51,142] {task_command.py:371} INFO - Running <TaskInstance: dag_weather.send_email manual__2023-07-13T18:53:39.043029+00:00 [running]> on host 6fc87d08a0f9
[2023-07-13 18:53:51,240] {taskinstance.py:1591} INFO - Exporting the following env vars:
AIRFLOW_CTX_DAG_OWNER=MariaRO
AIRFLOW_CTX_DAG_ID=dag_weather
AIRFLOW_CTX_TASK_ID=send_email
AIRFLOW_CTX_EXECUTION_DATE=2023-07-13T18:53:39.043029+00:00
AIRFLOW_CTX_TRY_NUMBER=1
AIRFLOW_CTX_DAG_RUN_ID=manual__2023-07-13T18:53:39.043029+00:00
[2023-07-13 18:53:51,250] {taskinstance.py:1909} ERROR - Task failed with exception
Traceback (most recent call last):
  File "/home/airflow/.local/lib/python3.7/site-packages/airflow/operators/python.py", line 171, in execute
    return_value = self.execute_callable()
  File "/home/airflow/.local/lib/python3.7/site-packages/airflow/operators/python.py", line 189, in execute_callable
    return self.python_callable(*self.op_args, **self.op_kwargs)
  File "/opt/airflow/dags/dag_weather.py", line 99, in send_email
    if df['rain'] == 1:
  File "/home/airflow/.local/lib/python3.7/site-packages/pandas/core/generic.py", line 1538, in __nonzero__
    f"The truth value of a {type(self).__name__} is ambiguous. "
ValueError: The truth value of a Series is ambiguous. Use a.empty, a.bool(), a.item(), a.any() or a.all().
[2023-07-13 18:53:51,262] {taskinstance.py:1420} INFO - Marking task as UP_FOR_RETRY. dag_id=dag_weather, task_id=send_email, execution_date=20230713T185339, start_date=20230713T185351, end_date=20230713T185351
[2023-07-13 18:53:51,276] {standard_task_runner.py:97} ERROR - Failed to execute job 77 for task send_email (The truth value of a Series is ambiguous. Use a.empty, a.bool(), a.item(), a.any() or a.all().; 232)
[2023-07-13 18:53:51,309] {local_task_job.py:156} INFO - Task exited with return code 1
[2023-07-13 18:53:51,351] {local_task_job.py:273} INFO - 0 downstream tasks scheduled from follow-on schedule check
