[2023-07-11 19:53:16,186] {taskinstance.py:1179} INFO - Dependencies all met for <TaskInstance: dag_weather.send_email manual__2023-07-11T19:52:59.934984+00:00 [queued]>
[2023-07-11 19:53:16,198] {taskinstance.py:1179} INFO - Dependencies all met for <TaskInstance: dag_weather.send_email manual__2023-07-11T19:52:59.934984+00:00 [queued]>
[2023-07-11 19:53:16,198] {taskinstance.py:1376} INFO - 
--------------------------------------------------------------------------------
[2023-07-11 19:53:16,198] {taskinstance.py:1377} INFO - Starting attempt 1 of 6
[2023-07-11 19:53:16,198] {taskinstance.py:1378} INFO - 
--------------------------------------------------------------------------------
[2023-07-11 19:53:16,215] {taskinstance.py:1397} INFO - Executing <Task(PythonOperator): send_email> on 2023-07-11 19:52:59.934984+00:00
[2023-07-11 19:53:16,219] {standard_task_runner.py:52} INFO - Started process 277 to run task
[2023-07-11 19:53:16,222] {standard_task_runner.py:79} INFO - Running: ['***', 'tasks', 'run', 'dag_weather', 'send_email', 'manual__2023-07-11T19:52:59.934984+00:00', '--job-id', '18', '--raw', '--subdir', 'DAGS_FOLDER/dag_weather.py', '--cfg-path', '/tmp/tmpo7cy330o', '--error-file', '/tmp/tmpurxtwjpd']
[2023-07-11 19:53:16,223] {standard_task_runner.py:80} INFO - Job 18: Subtask send_email
[2023-07-11 19:53:16,295] {task_command.py:371} INFO - Running <TaskInstance: dag_weather.send_email manual__2023-07-11T19:52:59.934984+00:00 [running]> on host b5f0b6584590
[2023-07-11 19:53:16,390] {taskinstance.py:1591} INFO - Exporting the following env vars:
AIRFLOW_CTX_DAG_OWNER=MariaRO
AIRFLOW_CTX_DAG_ID=dag_weather
AIRFLOW_CTX_TASK_ID=send_email
AIRFLOW_CTX_EXECUTION_DATE=2023-07-11T19:52:59.934984+00:00
AIRFLOW_CTX_TRY_NUMBER=1
AIRFLOW_CTX_DAG_RUN_ID=manual__2023-07-11T19:52:59.934984+00:00
[2023-07-11 19:53:16,392] {taskinstance.py:1909} ERROR - Task failed with exception
Traceback (most recent call last):
  File "/home/airflow/.local/lib/python3.7/site-packages/airflow/operators/python.py", line 171, in execute
    return_value = self.execute_callable()
  File "/home/airflow/.local/lib/python3.7/site-packages/airflow/operators/python.py", line 189, in execute_callable
    return self.python_callable(*self.op_args, **self.op_kwargs)
  File "/opt/airflow/dags/dag_weather.py", line 87, in send_email
    smtp_port, smtp_server, smtp_username, smtp_password = get_login(dag_path+"/.creds/smtp_pwd.txt")
  File "/opt/airflow/dags/weather_pckg/smtp_utils.py", line 4, in get_login
    creds = json.loads(creds)
NameError: name 'json' is not defined
[2023-07-11 19:53:16,401] {taskinstance.py:1420} INFO - Marking task as UP_FOR_RETRY. dag_id=dag_weather, task_id=send_email, execution_date=20230711T195259, start_date=20230711T195316, end_date=20230711T195316
[2023-07-11 19:53:16,417] {standard_task_runner.py:97} ERROR - Failed to execute job 18 for task send_email (name 'json' is not defined; 277)
[2023-07-11 19:53:16,434] {local_task_job.py:156} INFO - Task exited with return code 1
[2023-07-11 19:53:16,485] {local_task_job.py:273} INFO - 0 downstream tasks scheduled from follow-on schedule check
