[2023-07-11 19:29:55,845] {taskinstance.py:1179} INFO - Dependencies all met for <TaskInstance: dag_weather.upload_data scheduled__2023-07-10T00:00:00+00:00 [queued]>
[2023-07-11 19:29:55,862] {taskinstance.py:1179} INFO - Dependencies all met for <TaskInstance: dag_weather.upload_data scheduled__2023-07-10T00:00:00+00:00 [queued]>
[2023-07-11 19:29:55,863] {taskinstance.py:1376} INFO - 
--------------------------------------------------------------------------------
[2023-07-11 19:29:55,863] {taskinstance.py:1377} INFO - Starting attempt 1 of 6
[2023-07-11 19:29:55,863] {taskinstance.py:1378} INFO - 
--------------------------------------------------------------------------------
[2023-07-11 19:29:55,889] {taskinstance.py:1397} INFO - Executing <Task(PythonOperator): upload_data> on 2023-07-10 00:00:00+00:00
[2023-07-11 19:29:55,897] {standard_task_runner.py:52} INFO - Started process 265 to run task
[2023-07-11 19:29:55,906] {standard_task_runner.py:79} INFO - Running: ['***', 'tasks', 'run', 'dag_weather', 'upload_data', 'scheduled__2023-07-10T00:00:00+00:00', '--job-id', '8', '--raw', '--subdir', 'DAGS_FOLDER/dag_weather.py', '--cfg-path', '/tmp/tmpn3eb3qvh', '--error-file', '/tmp/tmpgmf1v3u2']
[2023-07-11 19:29:55,909] {standard_task_runner.py:80} INFO - Job 8: Subtask upload_data
[2023-07-11 19:29:56,032] {task_command.py:371} INFO - Running <TaskInstance: dag_weather.upload_data scheduled__2023-07-10T00:00:00+00:00 [running]> on host 7ee0c55ba55b
[2023-07-11 19:29:56,184] {taskinstance.py:1591} INFO - Exporting the following env vars:
AIRFLOW_CTX_DAG_OWNER=MariaRO
AIRFLOW_CTX_DAG_ID=dag_weather
AIRFLOW_CTX_TASK_ID=upload_data
AIRFLOW_CTX_EXECUTION_DATE=2023-07-10T00:00:00+00:00
AIRFLOW_CTX_TRY_NUMBER=1
AIRFLOW_CTX_DAG_RUN_ID=scheduled__2023-07-10T00:00:00+00:00
[2023-07-11 19:29:57,630] {logging_mixin.py:115} INFO - Connected to Redshift successfully!
[2023-07-11 19:29:59,038] {taskinstance.py:1909} ERROR - Task failed with exception
Traceback (most recent call last):
  File "/opt/airflow/dags/weather_pckg/redshift_utils.py", line 61, in load_to_redshift
    execute_values(cur, insert_sql, [values[i]])
  File "/home/airflow/.local/lib/python3.7/site-packages/psycopg2/extras.py", line 1270, in execute_values
    cur.execute(b''.join(parts))
psycopg2.errors.InternalError_: 1023
DETAIL:  Serializable isolation violation on table - 348533, transactions forming the cycle are: 15528431, 15528430 (pid:1073947413)


During handling of the above exception, another exception occurred:

Traceback (most recent call last):
  File "/home/airflow/.local/lib/python3.7/site-packages/airflow/operators/python.py", line 171, in execute
    return_value = self.execute_callable()
  File "/home/airflow/.local/lib/python3.7/site-packages/airflow/operators/python.py", line 189, in execute_callable
    return self.python_callable(*self.op_args, **self.op_kwargs)
  File "/opt/airflow/dags/dag_weather.py", line 79, in upload_data
    load_to_redshift(conn=conn_db_coder, table_name="forecast", dataframe=df)
  File "/opt/airflow/dags/weather_pckg/redshift_utils.py", line 65, in load_to_redshift
    raise Exception
Exception
[2023-07-11 19:29:59,048] {taskinstance.py:1420} INFO - Marking task as UP_FOR_RETRY. dag_id=dag_weather, task_id=upload_data, execution_date=20230710T000000, start_date=20230711T192955, end_date=20230711T192959
[2023-07-11 19:29:59,067] {standard_task_runner.py:97} ERROR - Failed to execute job 8 for task upload_data (; 265)
[2023-07-11 19:29:59,088] {local_task_job.py:156} INFO - Task exited with return code 1
[2023-07-11 19:29:59,159] {local_task_job.py:273} INFO - 0 downstream tasks scheduled from follow-on schedule check
