[2023-07-14 12:03:18,088] {taskinstance.py:1179} INFO - Dependencies all met for <TaskInstance: dag_weather.extract_data scheduled__2023-07-13T06:00:00+00:00 [queued]>
[2023-07-14 12:03:18,115] {taskinstance.py:1179} INFO - Dependencies all met for <TaskInstance: dag_weather.extract_data scheduled__2023-07-13T06:00:00+00:00 [queued]>
[2023-07-14 12:03:18,115] {taskinstance.py:1376} INFO - 
--------------------------------------------------------------------------------
[2023-07-14 12:03:18,115] {taskinstance.py:1377} INFO - Starting attempt 1 of 6
[2023-07-14 12:03:18,115] {taskinstance.py:1378} INFO - 
--------------------------------------------------------------------------------
[2023-07-14 12:03:18,184] {taskinstance.py:1397} INFO - Executing <Task(PythonOperator): extract_data> on 2023-07-13 06:00:00+00:00
[2023-07-14 12:03:18,191] {standard_task_runner.py:52} INFO - Started process 2101 to run task
[2023-07-14 12:03:18,196] {standard_task_runner.py:79} INFO - Running: ['***', 'tasks', 'run', 'dag_weather', 'extract_data', 'scheduled__2023-07-13T06:00:00+00:00', '--job-id', '10', '--raw', '--subdir', 'DAGS_FOLDER/dag_weather.py', '--cfg-path', '/tmp/tmpofe5hofv', '--error-file', '/tmp/tmpw_14d2cj']
[2023-07-14 12:03:18,198] {standard_task_runner.py:80} INFO - Job 10: Subtask extract_data
[2023-07-14 12:03:18,393] {task_command.py:371} INFO - Running <TaskInstance: dag_weather.extract_data scheduled__2023-07-13T06:00:00+00:00 [running]> on host c7e27842cc79
[2023-07-14 12:03:18,685] {taskinstance.py:1591} INFO - Exporting the following env vars:
AIRFLOW_CTX_DAG_OWNER=MariaRO
AIRFLOW_CTX_DAG_ID=dag_weather
AIRFLOW_CTX_TASK_ID=extract_data
AIRFLOW_CTX_EXECUTION_DATE=2023-07-13T06:00:00+00:00
AIRFLOW_CTX_TRY_NUMBER=1
AIRFLOW_CTX_DAG_RUN_ID=scheduled__2023-07-13T06:00:00+00:00
[2023-07-14 12:03:18,687] {logging_mixin.py:115} INFO - ***************
[2023-07-14 12:03:18,687] {logging_mixin.py:115} INFO - 2023-07-13
[2023-07-14 12:03:28,739] {logging_mixin.py:115} INFO - HTTPConnectionPool(host='api.weatherapi.com', port=80): Max retries exceeded with url: /v1/history.json?key=a6c998288a8944c8a84204951231505&q=Buenos%20Aires&dt=2023-07-10 (Caused by NewConnectionError('<urllib3.connection.HTTPConnection object at 0x7fc00435acd0>: Failed to establish a new connection: [Errno -3] Temporary failure in name resolution'))
[2023-07-14 12:03:31,830] {python.py:173} INFO - Done. Returned value was: None
[2023-07-14 12:03:31,849] {taskinstance.py:1420} INFO - Marking task as SUCCESS. dag_id=dag_weather, task_id=extract_data, execution_date=20230713T060000, start_date=20230714T120318, end_date=20230714T120331
[2023-07-14 12:03:31,891] {local_task_job.py:156} INFO - Task exited with return code 0
[2023-07-14 12:03:31,955] {local_task_job.py:273} INFO - 1 downstream tasks scheduled from follow-on schedule check
