[2023-06-19 20:28:22,219] {taskinstance.py:1179} INFO - Dependencies all met for <TaskInstance: dag_weather.transform_data manual__2023-06-19T20:07:56.990906+00:00 [queued]>
[2023-06-19 20:28:22,230] {taskinstance.py:1179} INFO - Dependencies all met for <TaskInstance: dag_weather.transform_data manual__2023-06-19T20:07:56.990906+00:00 [queued]>
[2023-06-19 20:28:22,230] {taskinstance.py:1376} INFO - 
--------------------------------------------------------------------------------
[2023-06-19 20:28:22,230] {taskinstance.py:1377} INFO - Starting attempt 1 of 6
[2023-06-19 20:28:22,230] {taskinstance.py:1378} INFO - 
--------------------------------------------------------------------------------
[2023-06-19 20:28:22,248] {taskinstance.py:1397} INFO - Executing <Task(PythonOperator): transform_data> on 2023-06-19 20:07:56.990906+00:00
[2023-06-19 20:28:22,252] {standard_task_runner.py:52} INFO - Started process 322 to run task
[2023-06-19 20:28:22,255] {standard_task_runner.py:79} INFO - Running: ['***', 'tasks', 'run', 'dag_weather', 'transform_data', 'manual__2023-06-19T20:07:56.990906+00:00', '--job-id', '73', '--raw', '--subdir', 'DAGS_FOLDER/dag_weather.py', '--cfg-path', '/tmp/tmpxnz5t7um', '--error-file', '/tmp/tmp998q0298']
[2023-06-19 20:28:22,256] {standard_task_runner.py:80} INFO - Job 73: Subtask transform_data
[2023-06-19 20:28:22,317] {task_command.py:371} INFO - Running <TaskInstance: dag_weather.transform_data manual__2023-06-19T20:07:56.990906+00:00 [running]> on host 871cafd9693a
[2023-06-19 20:28:22,393] {taskinstance.py:1591} INFO - Exporting the following env vars:
AIRFLOW_CTX_DAG_OWNER=MariaRO
AIRFLOW_CTX_DAG_ID=dag_weather
AIRFLOW_CTX_TASK_ID=transform_data
AIRFLOW_CTX_EXECUTION_DATE=2023-06-19T20:07:56.990906+00:00
AIRFLOW_CTX_TRY_NUMBER=1
AIRFLOW_CTX_DAG_RUN_ID=manual__2023-06-19T20:07:56.990906+00:00
[2023-06-19 20:28:22,409] {taskinstance.py:1909} ERROR - Task failed with exception
Traceback (most recent call last):
  File "/home/airflow/.local/lib/python3.7/site-packages/pandas/core/indexes/base.py", line 3361, in get_loc
    return self._engine.get_loc(casted_key)
  File "pandas/_libs/index.pyx", line 76, in pandas._libs.index.IndexEngine.get_loc
  File "pandas/_libs/index.pyx", line 108, in pandas._libs.index.IndexEngine.get_loc
  File "pandas/_libs/hashtable_class_helper.pxi", line 5198, in pandas._libs.hashtable.PyObjectHashTable.get_item
  File "pandas/_libs/hashtable_class_helper.pxi", line 5206, in pandas._libs.hashtable.PyObjectHashTable.get_item
KeyError: False

The above exception was the direct cause of the following exception:

Traceback (most recent call last):
  File "/home/airflow/.local/lib/python3.7/site-packages/airflow/operators/python.py", line 171, in execute
    return_value = self.execute_callable()
  File "/home/airflow/.local/lib/python3.7/site-packages/airflow/operators/python.py", line 189, in execute_callable
    return self.python_callable(*self.op_args, **self.op_kwargs)
  File "/opt/airflow/dags/dag_weather.py", line 65, in transform_data
    df = df[df["date" == exec_date]]
  File "/home/airflow/.local/lib/python3.7/site-packages/pandas/core/frame.py", line 3458, in __getitem__
    indexer = self.columns.get_loc(key)
  File "/home/airflow/.local/lib/python3.7/site-packages/pandas/core/indexes/base.py", line 3363, in get_loc
    raise KeyError(key) from err
KeyError: False
[2023-06-19 20:28:22,418] {taskinstance.py:1420} INFO - Marking task as UP_FOR_RETRY. dag_id=dag_weather, task_id=transform_data, execution_date=20230619T200756, start_date=20230619T202822, end_date=20230619T202822
[2023-06-19 20:28:22,429] {standard_task_runner.py:97} ERROR - Failed to execute job 73 for task transform_data (False; 322)
[2023-06-19 20:28:22,468] {local_task_job.py:156} INFO - Task exited with return code 1
[2023-06-19 20:28:22,551] {local_task_job.py:273} INFO - 0 downstream tasks scheduled from follow-on schedule check
