[2023-07-14 12:03:54,858] {taskinstance.py:1179} INFO - Dependencies all met for <TaskInstance: dag_weather.send_email scheduled__2023-07-13T06:00:00+00:00 [queued]>
[2023-07-14 12:03:54,881] {taskinstance.py:1179} INFO - Dependencies all met for <TaskInstance: dag_weather.send_email scheduled__2023-07-13T06:00:00+00:00 [queued]>
[2023-07-14 12:03:54,881] {taskinstance.py:1376} INFO - 
--------------------------------------------------------------------------------
[2023-07-14 12:03:54,881] {taskinstance.py:1377} INFO - Starting attempt 1 of 6
[2023-07-14 12:03:54,881] {taskinstance.py:1378} INFO - 
--------------------------------------------------------------------------------
[2023-07-14 12:03:54,943] {taskinstance.py:1397} INFO - Executing <Task(PythonOperator): send_email> on 2023-07-13 06:00:00+00:00
[2023-07-14 12:03:54,950] {standard_task_runner.py:52} INFO - Started process 2126 to run task
[2023-07-14 12:03:54,956] {standard_task_runner.py:79} INFO - Running: ['***', 'tasks', 'run', 'dag_weather', 'send_email', 'scheduled__2023-07-13T06:00:00+00:00', '--job-id', '13', '--raw', '--subdir', 'DAGS_FOLDER/dag_weather.py', '--cfg-path', '/tmp/tmpcnlu1dob', '--error-file', '/tmp/tmp096i7476']
[2023-07-14 12:03:54,958] {standard_task_runner.py:80} INFO - Job 13: Subtask send_email
[2023-07-14 12:03:55,157] {task_command.py:371} INFO - Running <TaskInstance: dag_weather.send_email scheduled__2023-07-13T06:00:00+00:00 [running]> on host c7e27842cc79
[2023-07-14 12:03:55,746] {taskinstance.py:1591} INFO - Exporting the following env vars:
AIRFLOW_CTX_DAG_OWNER=MariaRO
AIRFLOW_CTX_DAG_ID=dag_weather
AIRFLOW_CTX_TASK_ID=send_email
AIRFLOW_CTX_EXECUTION_DATE=2023-07-13T06:00:00+00:00
AIRFLOW_CTX_TRY_NUMBER=1
AIRFLOW_CTX_DAG_RUN_ID=scheduled__2023-07-13T06:00:00+00:00
[2023-07-14 12:03:55,797] {taskinstance.py:1909} ERROR - Task failed with exception
Traceback (most recent call last):
  File "/home/airflow/.local/lib/python3.7/site-packages/airflow/operators/python.py", line 171, in execute
    return_value = self.execute_callable()
  File "/home/airflow/.local/lib/python3.7/site-packages/airflow/operators/python.py", line 189, in execute_callable
    return self.python_callable(*self.op_args, **self.op_kwargs)
  File "/opt/airflow/dags/dag_weather.py", line 142, in send_email
    with smtplib.SMTP(smtp_server, smtp_port) as server:
  File "/usr/local/lib/python3.7/smtplib.py", line 251, in __init__
    (code, msg) = self.connect(host, port)
  File "/usr/local/lib/python3.7/smtplib.py", line 336, in connect
    self.sock = self._get_socket(host, port, self.timeout)
  File "/usr/local/lib/python3.7/smtplib.py", line 307, in _get_socket
    self.source_address)
  File "/usr/local/lib/python3.7/socket.py", line 707, in create_connection
    for res in getaddrinfo(host, port, 0, SOCK_STREAM):
  File "/usr/local/lib/python3.7/socket.py", line 752, in getaddrinfo
    for res in _socket.getaddrinfo(host, port, family, type, proto, flags):
socket.gaierror: [Errno -2] Name or service not known
[2023-07-14 12:03:55,815] {taskinstance.py:1420} INFO - Marking task as UP_FOR_RETRY. dag_id=dag_weather, task_id=send_email, execution_date=20230713T060000, start_date=20230714T120354, end_date=20230714T120355
[2023-07-14 12:03:55,838] {standard_task_runner.py:97} ERROR - Failed to execute job 13 for task send_email ([Errno -2] Name or service not known; 2126)
[2023-07-14 12:03:55,851] {local_task_job.py:156} INFO - Task exited with return code 1
[2023-07-14 12:03:55,913] {local_task_job.py:273} INFO - 0 downstream tasks scheduled from follow-on schedule check
