[2023-06-26 12:21:37,166] {taskinstance.py:1179} INFO - Dependencies all met for <TaskInstance: dag_weather.upload_data scheduled__2023-06-25T00:00:00+00:00 [queued]>
[2023-06-26 12:21:37,183] {taskinstance.py:1179} INFO - Dependencies all met for <TaskInstance: dag_weather.upload_data scheduled__2023-06-25T00:00:00+00:00 [queued]>
[2023-06-26 12:21:37,183] {taskinstance.py:1376} INFO - 
--------------------------------------------------------------------------------
[2023-06-26 12:21:37,183] {taskinstance.py:1377} INFO - Starting attempt 1 of 6
[2023-06-26 12:21:37,184] {taskinstance.py:1378} INFO - 
--------------------------------------------------------------------------------
[2023-06-26 12:21:37,206] {taskinstance.py:1397} INFO - Executing <Task(PythonOperator): upload_data> on 2023-06-25 00:00:00+00:00
[2023-06-26 12:21:37,211] {standard_task_runner.py:52} INFO - Started process 4272 to run task
[2023-06-26 12:21:37,215] {standard_task_runner.py:79} INFO - Running: ['***', 'tasks', 'run', 'dag_weather', 'upload_data', 'scheduled__2023-06-25T00:00:00+00:00', '--job-id', '112', '--raw', '--subdir', 'DAGS_FOLDER/dag_weather.py', '--cfg-path', '/tmp/tmpwmig9039', '--error-file', '/tmp/tmpcnnxxs_4']
[2023-06-26 12:21:37,216] {standard_task_runner.py:80} INFO - Job 112: Subtask upload_data
[2023-06-26 12:21:37,324] {task_command.py:371} INFO - Running <TaskInstance: dag_weather.upload_data scheduled__2023-06-25T00:00:00+00:00 [running]> on host db753b024971
[2023-06-26 12:21:37,423] {taskinstance.py:1591} INFO - Exporting the following env vars:
AIRFLOW_CTX_DAG_OWNER=MariaRO
AIRFLOW_CTX_DAG_ID=dag_weather
AIRFLOW_CTX_TASK_ID=upload_data
AIRFLOW_CTX_EXECUTION_DATE=2023-06-25T00:00:00+00:00
AIRFLOW_CTX_TRY_NUMBER=1
AIRFLOW_CTX_DAG_RUN_ID=scheduled__2023-06-25T00:00:00+00:00
[2023-06-26 12:21:37,436] {logging_mixin.py:115} INFO - Unable to connect to Redshift.
[2023-06-26 12:21:37,436] {logging_mixin.py:115} INFO - could not translate host name "data-engineer-cluster.cyhh5bfevlmn.us-east-1.redshift.amazonaws.com" to address: Name or service not known
[2023-06-26 12:21:37,438] {taskinstance.py:1909} ERROR - Task failed with exception
Traceback (most recent call last):
  File "/home/airflow/.local/lib/python3.7/site-packages/airflow/operators/python.py", line 171, in execute
    return_value = self.execute_callable()
  File "/home/airflow/.local/lib/python3.7/site-packages/airflow/operators/python.py", line 189, in execute_callable
    return self.python_callable(*self.op_args, **self.op_kwargs)
  File "/opt/airflow/dags/dag_weather.py", line 73, in upload_data
    load_to_redshift(conn=conn_db_coder, table_name="forecast", dataframe=df)
  File "/opt/airflow/dags/weather_pckg/redshift_utils.py", line 29, in load_to_redshift
    cur = conn.cursor()
AttributeError: 'NoneType' object has no attribute 'cursor'
[2023-06-26 12:21:37,448] {taskinstance.py:1420} INFO - Marking task as UP_FOR_RETRY. dag_id=dag_weather, task_id=upload_data, execution_date=20230625T000000, start_date=20230626T122137, end_date=20230626T122137
[2023-06-26 12:21:37,462] {standard_task_runner.py:97} ERROR - Failed to execute job 112 for task upload_data ('NoneType' object has no attribute 'cursor'; 4272)
[2023-06-26 12:21:37,507] {local_task_job.py:156} INFO - Task exited with return code 1
[2023-06-26 12:21:37,543] {local_task_job.py:273} INFO - 0 downstream tasks scheduled from follow-on schedule check
