[2023-07-11 19:29:59,898] {taskinstance.py:1179} INFO - Dependencies all met for <TaskInstance: dag_weather.send_email manual__2023-07-11T19:29:47.561623+00:00 [queued]>
[2023-07-11 19:29:59,913] {taskinstance.py:1179} INFO - Dependencies all met for <TaskInstance: dag_weather.send_email manual__2023-07-11T19:29:47.561623+00:00 [queued]>
[2023-07-11 19:29:59,913] {taskinstance.py:1376} INFO - 
--------------------------------------------------------------------------------
[2023-07-11 19:29:59,913] {taskinstance.py:1377} INFO - Starting attempt 1 of 6
[2023-07-11 19:29:59,914] {taskinstance.py:1378} INFO - 
--------------------------------------------------------------------------------
[2023-07-11 19:29:59,937] {taskinstance.py:1397} INFO - Executing <Task(PythonOperator): send_email> on 2023-07-11 19:29:47.561623+00:00
[2023-07-11 19:29:59,943] {standard_task_runner.py:52} INFO - Started process 273 to run task
[2023-07-11 19:29:59,948] {standard_task_runner.py:79} INFO - Running: ['***', 'tasks', 'run', 'dag_weather', 'send_email', 'manual__2023-07-11T19:29:47.561623+00:00', '--job-id', '9', '--raw', '--subdir', 'DAGS_FOLDER/dag_weather.py', '--cfg-path', '/tmp/tmp_mj63x1e', '--error-file', '/tmp/tmpw7jf83pb']
[2023-07-11 19:29:59,950] {standard_task_runner.py:80} INFO - Job 9: Subtask send_email
[2023-07-11 19:30:00,055] {task_command.py:371} INFO - Running <TaskInstance: dag_weather.send_email manual__2023-07-11T19:29:47.561623+00:00 [running]> on host 7ee0c55ba55b
[2023-07-11 19:30:00,200] {taskinstance.py:1591} INFO - Exporting the following env vars:
AIRFLOW_CTX_DAG_OWNER=MariaRO
AIRFLOW_CTX_DAG_ID=dag_weather
AIRFLOW_CTX_TASK_ID=send_email
AIRFLOW_CTX_EXECUTION_DATE=2023-07-11T19:29:47.561623+00:00
AIRFLOW_CTX_TRY_NUMBER=1
AIRFLOW_CTX_DAG_RUN_ID=manual__2023-07-11T19:29:47.561623+00:00
[2023-07-11 19:30:00,275] {taskinstance.py:1909} ERROR - Task failed with exception
Traceback (most recent call last):
  File "/home/airflow/.local/lib/python3.7/site-packages/airflow/operators/python.py", line 171, in execute
    return_value = self.execute_callable()
  File "/home/airflow/.local/lib/python3.7/site-packages/airflow/operators/python.py", line 189, in execute_callable
    return self.python_callable(*self.op_args, **self.op_kwargs)
  File "/opt/airflow/dags/dag_weather.py", line 109, in send_email
    with smtplib.SMTP(smtp_server, smtp_port) as server:
  File "/usr/local/lib/python3.7/smtplib.py", line 251, in __init__
    (code, msg) = self.connect(host, port)
  File "/usr/local/lib/python3.7/smtplib.py", line 336, in connect
    self.sock = self._get_socket(host, port, self.timeout)
  File "/usr/local/lib/python3.7/smtplib.py", line 307, in _get_socket
    self.source_address)
  File "/usr/local/lib/python3.7/socket.py", line 707, in create_connection
    for res in getaddrinfo(host, port, 0, SOCK_STREAM):
  File "/usr/local/lib/python3.7/socket.py", line 752, in getaddrinfo
    for res in _socket.getaddrinfo(host, port, family, type, proto, flags):
socket.gaierror: [Errno -2] Name or service not known
[2023-07-11 19:30:00,291] {taskinstance.py:1420} INFO - Marking task as UP_FOR_RETRY. dag_id=dag_weather, task_id=send_email, execution_date=20230711T192947, start_date=20230711T192959, end_date=20230711T193000
[2023-07-11 19:30:00,307] {standard_task_runner.py:97} ERROR - Failed to execute job 9 for task send_email ([Errno -2] Name or service not known; 273)
[2023-07-11 19:30:00,320] {local_task_job.py:156} INFO - Task exited with return code 1
[2023-07-11 19:30:00,364] {local_task_job.py:273} INFO - 0 downstream tasks scheduled from follow-on schedule check
